Workbook
Name Slicer_Status1: #N/A

Sheet Data_Mentah
A1: No | B1: ID Prov | C1: Provinsi | D1: ID KAB | E1: Kabupaten | F1: Nama Kawasan | G1: Dimensi Manajemen dan Tata Kelola | H1: Dimensi Sarana dan Prasaran | I1: Dimensi Interaksi Kawasan | J1: Dimensi Aktivitas Ekonomi | K1: Total Nilai | L1: Status
A2: 1 | B2: 33 | C2: Jawa Tengah | D2: 3313 | E2: Karanganyar | F2: Kawasan Perdesaan Agrowisata Ngargoyoso | G2: 25.8 | H2: 18.4 | I2: 14.43 | J2: 16.78 | K2: 75.41 | L2: Berdaya Saing
A3: 2 | B3: 63 | C3: Kalimantan Selatan | D3: 6310 | E3: Tanah Bumbu | F3: Kawasan Perdesaan Agropolitan Tanah Bumbu | G3: 28.46 | H3: 17.71 | I3: 17.13 | J3: 12.54 | K3: 75.84 | L3: Berdaya Saing
A4: 3 | B4: 33 | C4: Jawa Tengah | D4: 3307 | E4: Wonosobo | F4: Kawasan Perdesaan Margomarem | G4: 28.34 | H4: 18.4 | I4: 17.85 | J4: 10.7 | K4: 75.29 | L4: Berdaya Saing
A5: 4 | B5: 51 | C5: Bali | D5: 5102 | E5: Tabanan | F5: Kawasan Perdesaan Shiny Tabanan Yang Alami, Berbudaya, Dan Berkedaulatan Pangan | G5: 25.88 | H5: 18.8 | I5: 13.72 | J5: 16.64 | K5: 75.05 | L5: Berdaya Saing
A6: 5 | B6: 12 | C6: Sumatera Utara | D6: 1212 | E6: Toba | F6: Kawasan Perdesaan Ajibata | G6: 27.4 | H6: 17.6 | I6: 15.7 | J6: 13.02 | K6: 73.72 | L6: Mandiri
A7: 6 | B7: 32 | C7: Jawa Barat | D7: 3205 | E7: Garut | F7: Kawasan Perdesaan Industri Bambu Kreatif Selaawi | G7: 23.8 | H7: 18.4 | I7: 13.72 | J7: 16.1 | K7: 72.02 | L7: Mandiri
A8: 7 | B8: 15 | C8: Jambi | D8: 1509 | E8: Tebo | F8: Kawasan Perdesaan Mina-agro-wisata | G8: 31.32 | H8: 17.2 | I8: 12.78 | J8: 8.9 | K8: 70.2 | L8: Mandiri
A9: 8 | B9: 61 | C9: Kalimantan Barat | D9: 6112 | E9: Kubu Raya | F9: Kawasan Perdesaan Pertanian Terpadu Sungai Kakap | G9: 27.58 | H9: 18.4 | I9: 14.98 | J9: 4.32 | K9: 65.28 | L9: Mandiri
A10: 9 | B10: 13 | C10: Sumatera Barat | D10: 1306 | E10: Agam | F10: Kawasan Perdesaan Agribisnis Pamako | G10: 23.12 | H10: 18 | I10: 14.98 | J10: 8.46 | K10: 64.56 | L10: Mandiri
A11: 10 | B11: 63 | C11: Kalimantan Selatan | D11: 6309 | E11: Tabalong | F11: Kawasan Perdesaan Agrowisata Hortikultura | G11: 26.14 | H11: 16.51 | I11: 14.98 | J11: 6.78 | K11: 64.41 | L11: Mandiri
A12: 11 | B12: 17 | C12: Bengkulu | D12: 1701 | E12: Bengkulu Selatan | F12: Kawasan Food Estate Berbasis Korporasi Petani | G12: 26.18 | H12: 18.11 | I12: 11.9 | J12: 3.46 | K12: 59.65 | L12: Mandiri
A13: 12 | B13: 33 | C13: Jawa Tengah | D13: 3324 | E13: Kendal | F13: Kawasan Perdesaan Plasma Petik Sari | G13: 22.66 | H13: 18 | I13: 9.58 | J13: 8.38 | K13: 58.62 | L13: Mandiri
... A31: 30 | B31: 96 | C31: Papua Barat Daya | D31: 9603 | E31: Raja Ampat | F31: Kawasan Perdesaan Misool | G31: 2.04 | H31: 8.86 | I31: 3.8 | J31: 0 | K31: 14.7 | L31: Inisiasi

Sheet Pertanyaan & Jawaban (Insight)
A1: PERTANYAAN 1: Bagaimana distribusi klasifikasi Status pembangunan kawasan perdesaan (misalnya 'Berdaya Saing') pada keseluruhan data?
A3: Row Labels | B3: Count of Nama Kawasan
A4: Berdaya Saing | B4: 4
A5: Inisiasi | B5: 1
A6: Konsolidasi | B6: 12
A7: Mandiri | B7: 13
A8: Grand Total | B8: 30 | L8: JAWABAN / INSIGHT: Dari 30 kawasan: Mandiri 13 (43%), Konsolidasi 12 (40%), Berdaya Saing 4 (13%), Inisiasi 1 (3%). Jadi mayoritas kawasan (83%) masih di level menengah (Mandiri+Konsolidasi); baru 13% yang sudah mencapai status tertinggi 'Berdaya Saing'.
A19: PERTANYAAN 2: Provinsi atau Kabupaten manakah yang memiliki rata-rata Total Nilai Indeks Pembangunan Kawasan Perdesaan tertinggi?
A21: Row Labels | B21: Average of Total Nilai
A22: Aceh | B22: 52.78
A23: Bali | B23: 64.895 | L23: JAWABAN / INSIGHT: Peta ini melengkapi jawaban Pertanyaan 2 secara geografis: provinsi-provinsi di Sumatera dan Jawa bagian tengah cenderung punya warna lebih pekat (nilai lebih tinggi) dibanding provinsi di kawasan timur Indonesia seperti Papua.
A24: Banten | B24: 45.79
A25: Bengkulu | B25: 59.65
A26: Jambi | B26: 70.2
A27: Jawa Barat | B27: 57.326667
A28: Jawa Tengah | B28: 69.773333
A29: Jawa Timur | B29: 49.88
A30: Kalimantan Barat | B30: 65.28
A31: Kalimantan Selatan | B31: 66.286667
A32: Kalimantan Timur | B32: 34.6
A33: Kepulauan Bangka Belitung | B33: 52.53
A34: Maluku | B34: 48.37
A35: Maluku Utara | B35: 40.05
... A45: Grand Total | B45: 54.049
A47: PERTANYAAN 3: Dari keempat dimensi yang diukur, dimensi manakah (Manajemen, Sarpras, Interaksi, atau Ekonomi) yang menyumbang rata-rata proporsi nilai tertinggi terhadap Total Nilai?
A50: Dimensi
A51: Average of Dimensi Aktivitas Ekonomi | B51: 5.3573333 | J51: JAWABAN / INSIGHT: Dimensi Manajemen dan Tata Kelola merupakan penyumbang skor terbesar. Sementara itu, Dimensi Aktivitas Ekonomi cenderung lebih rendah, menandakan perlunya stimulus ekonomi di kawasan perdesaan.
A52: Average of Dimensi Interaksi Kawasan | B52: 12.083333
A53: Average of Dimensi Sarana dan Prasaran | B53: 16.273667
A54: Average of Dimensi Manajemen dan Tata Kelola | B54: 20.334
A67: PERTANYAAN 4: Apakah terdapat korelasi positif antara tingginya skor Dimensi Aktivitas Ekonomi dengan tercapainya status kawasan yang berdaya saing?
A69: Aktivitas Ekonomi | B69: Total Nilai
A70: 16.78 | B70: 75.41
A71: 12.54 | B71: 75.84 | J71: JAWABAN / INSIGHT: Plot sebaran menunjukkan pola linier positif yang kuat. Artinya, setiap peningkatan intervensi pada sektor aktivitas ekonomi akan sangat berdampak pada kenaikan daya saing kawasan secara keseluruhan (Total Nilai).
A72: 10.7 | B72: 75.29
A73: 16.64 | B73: 75.05
A74: 13.02 | B74: 73.72
A75: 16.1 | B75: 72.02
A76: 8.9 | B76: 70.2
A77: 4.32 | B77: 65.28
...

Sheet Statistik Dasar
B1: Mean (Central Tendency) | C1: Median (Central Tendency) | D1: Mode (Central Tendency) | E1: Std Dev (Dispersion) | F1: Variance (Dispersion) | G1: Min (Dispersion) | H1: Max (Dispersion) | I1: Skewness (Asymmetric) | J1: Kurtosis (Asymmetric)
A2: Dimensi Manajemen dan Tata Kelola | B2: =AVERAGE(Data_Mentah!G2:G31) -> 20.334 | C2: =MEDIAN(Data_Mentah!G2:G31) -> 21.71 | D2: =IFERROR(MODE(Data_Mentah!G2:G31),"Tidak ada modus (semua nilai unik)") -> Tidak ada modus (semua nilai unik) | E2: =STDEV(Data_Mentah!G2:G31) -> 6.9654995 | F2: =VAR(Data_Mentah!G2:G31) -> 48.518183 | G2: =MIN(Data_Mentah!G2:G31) -> 2.04 | H2: =MAX(Data_Mentah!G2:G31) -> 31.32 | I2: =SKEW(Data_Mentah!G2:G31) -> -0.92290913 | J2: =KURT(Data_Mentah!G2:G31) -> 0.77943601
A3: Dimensi Sarana dan Prasaran | B3: =AVERAGE(Data_Mentah!H2:H31) -> 16.273667 | C3: =MEDIAN(Data_Mentah!H2:H31) -> 16.655 | D3: =IFERROR(MODE(Data_Mentah!H2:H31),"Tidak ada modus (semua nilai unik)") -> 18.4 | E3: =STDEV(Data_Mentah!H2:H31) -> 2.3519419 | F3: =VAR(Data_Mentah!H2:H31) -> 5.5316309 | G3: =MIN(Data_Mentah!H2:H31) -> 8.86 | H3: =MAX(Data_Mentah!H2:H31) -> 19.2 | I3: =SKEW(Data_Mentah!H2:H31) -> -1.3980107 | J3: =KURT(Data_Mentah!H2:H31) -> 2.1465101
A4: Dimensi Interaksi Kawasan | B4: =AVERAGE(Data_Mentah!I2:I31) -> 12.083333 | C4: =MEDIAN(Data_Mentah!I2:I31) -> 13.165 | D4: =IFERROR(MODE(Data_Mentah!I2:I31),"Tidak ada modus (semua nilai unik)") -> 14.98 | E4: =STDEV(Data_Mentah!I2:I31) -> 3.5463836 | F4: =VAR(Data_Mentah!I2:I31) -> 12.576837 | G4: =MIN(Data_Mentah!I2:I31) -> 3.8 | H4: =MAX(Data_Mentah!I2:I31) -> 17.85 | I4: =SKEW(Data_Mentah!I2:I31) -> -0.59884393 | J4: =KURT(Data_Mentah!I2:I31) -> -0.42059564
A5: Dimensi Aktivitas Ekonomi | B5: =AVERAGE(Data_Mentah!J2:J31) -> 5.3573333 | C5: =MEDIAN(Data_Mentah!J2:J31) -> 3.53 | D5: =IFERROR(MODE(Data_Mentah!J2:J31),"Tidak ada modus (semua nilai unik)") -> 0 | E5: =STDEV(Data_Mentah!J2:J31) -> 5.5080373 | F5: =VAR(Data_Mentah!J2:J31) -> 30.338475 | G5: =MIN(Data_Mentah!J2:J31) -> 0 | H5: =MAX(Data_Mentah!J2:J31) -> 16.78 | I5: =SKEW(Data_Mentah!J2:J31) -> 0.80674168 | J5: =KURT(Data_Mentah!J2:J31) -> -0.47775066
A6: Total Nilai | B6: =AVERAGE(Data_Mentah!K2:K31) -> 54.049 | C6: =MEDIAN(Data_Mentah!K2:K31) -> 53.76 | D6: =IFERROR(MODE(Data_Mentah!K2:K31),"Tidak ada modus (semua nilai unik)") -> Tidak ada modus (semua nilai unik) | E6: =STDEV(Data_Mentah!K2:K31) -> 15.588435 | F6: =VAR(Data_Mentah!K2:K31) -> 242.99931 | G6: =MIN(Data_Mentah!K2:K31) -> 14.7 | H6: =MAX(Data_Mentah!K2:K31) -> 75.84 | I6: =SKEW(Data_Mentah!K2:K31) -> -0.40038662 | J6: =KURT(Data_Mentah!K2:K31) -> -0.18080969
A8: Data Relationship (Korelasi Antar Dimensi)
B9: Dimensi Manajemen dan Tata Kelola | C9: Dimensi Sarana dan Prasaran | D9: Dimensi Interaksi Kawasan | E9: Dimensi Aktivitas Ekonomi | F9: Total Nilai
A10: Dimensi Manajemen dan Tata Kelola | B10: 1 | C10: =CORREL(Data_Mentah!G2:G31,Data_Mentah!H2:H31) -> 0.6069444 | D10: =CORREL(Data_Mentah!G2:G31,Data_Mentah!I2:I31) -> 0.59926853 | E10: =CORREL(Data_Mentah!G2:G31,Data_Mentah!J2:J31) -> 0.6513058 | F10: =CORREL(Data_Mentah!G2:G31,Data_Mentah!K2:K31) -> 0.90487763
A11: Dimensi Sarana dan Prasaran | B11: =CORREL(Data_Mentah!H2:H31,Data_Mentah!G2:G31) -> 0.6069444 | C11: 1 | D11: =CORREL(Data_Mentah!H2:H31,Data_Mentah!I2:I31) -> 0.71303921 | E11: =CORREL(Data_Mentah!H2:H31,Data_Mentah!J2:J31) -> 0.59517181 | F11: =CORREL(Data_Mentah!H2:H31,Data_Mentah!K2:K31) -> 0.79458172
A12: Dimensi Interaksi Kawasan | B12: =CORREL(Data_Mentah!I2:I31,Data_Mentah!G2:G31) -> 0.59926853 | C12: =CORREL(Data_Mentah!I2:I31,Data_Mentah!H2:H31) -> 0.71303921 | D12: 1 | E12: =CORREL(Data_Mentah!I2:I31,Data_Mentah!J2:J31) -> 0.49274791 | F12: =CORREL(Data_Mentah!I2:I31,Data_Mentah!K2:K31) -> 0.77693721
A13: Dimensi Aktivitas Ekonomi | B13: =CORREL(Data_Mentah!J2:J31,Data_Mentah!G2:G31) -> 0.6513058 | C13: =CORREL(Data_Mentah!J2:J31,Data_Mentah!H2:H31) -> 0.59517181 | D13: =CORREL(Data_Mentah!J2:J31,Data_Mentah!I2:I31) -> 0.49274791 | E13: 1 | F13: =CORREL(Data_Mentah!J2:J31,Data_Mentah!K2:K31) -> 0.84629157
A14: Total Nilai | B14: =CORREL(Data_Mentah!K2:K31,Data_Mentah!G2:G31) -> 0.90487763 | C14: =CORREL(Data_Mentah!K2:K31,Data_Mentah!H2:H31) -> 0.79458172 | D14: =CORREL(Data_Mentah!K2:K31,Data_Mentah!I2:I31) -> 0.77693721 | E14: =CORREL(Data_Mentah!K2:K31,Data_Mentah!J2:J31) -> 0.84629157 | F14: 1
